Workbook

Sheet Udyoga Bhawan
A1: Table A : Ambient Air Quality Data for SO2 and NOx under NAMP monitored by Walchand College of Engg,. Sangli.
A2: Sampling Location : Udyoga Bhawan, Sangli.
A3: City : Sangli. | G3: Month: January 2024 | K3: n | M3: Parameter | O3: Unit
A4: State : Maharashtra | K4: am | M4: SO2 | O4: µg/m3
A5: Station Type :Residential | K5: sd | M5: NOx | O5: µg/m3
A6: Code No. :-574 | G6: Industrial | K6: p
A7: ** Monitoring could not be done due to power cut off or maintenance of machine
A10: Sr No | B10: Date | C10: SO2 | I10: 4 hrs | J10: 24 hrs | K10: NOx | Q10: 4 hrs | R10: 24 hrs | S10: Weather Cond.n
C11: 08--12 | D11: 12--16 | E11: 16--20 | F11: 20--24 | G11: 00-04 | H11: 04--08 | I11: Max | J11: Avg | K11: 08--12 | L11: 12--16 | M11: 16--20 | N11: 20--24 | O11: 00--04 | P11: 04--08 | Q11: Max | R11: Avg | S11: Max | T11: Min
A12: 1 | B12: 45295 | C12: =[1]Air!$D$4 -> 11.298246 | D12: =[1]Air!$D$5 -> 10.861111 | E12: =[1]Air!$D$6 -> 12.710526 | F12: =[1]Air!$D$7 -> 14.162037 | G12: =[1]Air!$D$8 -> 14.907407 | H12: =[1]Air!$D$9 -> 10.435185 | I12: =MAX(C12:H12) -> 14.907407 | J12: =AVERAGE(C12:H12) -> 12.395752 | K12: =[1]Air!$U$4 -> 31.230087 | L12: =[1]Air!$U$4 -> 31.230087 | M12: =[1]Air!$U$5 -> 30.396904 | N12: =[1]Air!$U$6 -> 37.933392 | O12: =[1]Air!$U$7 -> 40.824602 | P12: =[1]Air!$U$8 -> 40.803761 | Q12: =MAX(K12:P12) -> 40.824602 | R12: =AVERAGE(K12:P12) -> 35.403139
A13: 2 | B13: 45298 | C13: =[1]Air!$D$10 -> 9.5833333 | D13: =[1]Air!$D$11 -> 10.733333 | E13: =[1]Air!$D$12 -> 9.8859649 | F13: =[1]Air!$D$13 -> 11.925926 | G13: =[1]Air!$D$14 -> 9.6898148 | H13: =[1]Air!$D$15 -> 7.4537037 | I13: =MAX(C13:H13) -> 11.925926 | J13: =AVERAGE(C13:H13) -> 9.8786793 | K13: =[1]Air!$U$10 -> 29.088976 | L13: =[1]Air!$U$11 -> 31.704832 | M13: =[1]Air!$U$12 -> 68.291093 | N13: =[1]Air!$U$13 -> 47.329823 | O13: =[1]Air!$U$14 -> 49.1963 | P13: =[1]Air!$U$15 -> 46.144468 | Q13: =MAX(K13:P13) -> 68.291093 | R13: =AVERAGE(K13:P13) -> 45.292582
A14: 3 | B14: 45302 | C14: =[1]Air!$D$16 -> 7.6666667 | D14: =[1]Air!$D$17 -> 9.3916667 | E14: =[1]Air!$D$18 -> 10.0625 | F14: =[1]Air!$D$19 -> 9.6898148 | G14: =[1]Air!$D$20 -> 11.180556 | H14: =[1]Air!$D$21 -> 10.435185 | I14: =MAX(C14:H14) -> 11.180556 | J14: =AVERAGE(C14:H14) -> 9.7377315 | K14: =[1]Air!$U$16 -> 50.015826 | L14: =[1]Air!$U$17 -> 51.323754 | M14: =[1]Air!$U$18 -> 48.707898 | N14: =[1]Air!$U$19 -> 52.38944 | O14: =[1]Air!$U$20 -> 56.062923 | P14: =[1]Air!$U$21 -> 57.588839 | Q14: =MAX(K14:P14) -> 57.588839 | R14: =AVERAGE(K14:P14) -> 52.681447
A15: 4 | B15: 45305 | C15: =[1]Air!$D$22 -> 11.298246 | D15: =[1]Air!$D$23 -> 9.8859649 | E15: =[1]Air!$D$24 -> 12.004386 | F15: =[1]Air!$D$25 -> 12.710526 | G15: =[1]Air!$D$26 -> 12.710526 | H15: =[1]Air!$D$27 -> 11.298246 | I15: =MAX(C15:H15) -> 12.710526 | J15: =AVERAGE(C15:H15) -> 11.651316 | K15: =[1]Air!$U$22 -> 53.889942 | L15: =[1]Air!$U$23 -> 53.835045 | M15: =[1]Air!$U$24 -> 55.299965 | N15: =[1]Air!$U$25 -> 50.943835 | O15: =[1]Air!$U$26 -> 38.656195 | P15: =[1]Air!$U$27 -> 38.656195 | Q15: =MAX(K15:P15) -> 55.299965 | R15: =AVERAGE(K15:P15) -> 48.546863
A16: 5 | B16: 45309 | C16: =[1]Air!$D$28 -> 9.8859649 | D16: =[1]Air!$D$29 -> 10.592105 | E16: =[1]Air!$D$30 -> 12.004386 | F16: =[1]Air!$D$31 -> 12.710526 | G16: =[1]Air!$D$32 -> 11.298246 | H16: =[1]Air!$D$33 -> 12.671296 | I16: =MAX(C16:H16) -> 12.710526 | J16: =AVERAGE(C16:H16) -> 11.527087 | K16: =[1]Air!$U$28 -> 60.756564 | L16: =[1]Air!$U$29 -> 60.069902 | M16: =[1]Air!$U$30 -> 63.503214 | N16: =[1]Air!$U$31 -> 67.56829 | O16: =[1]Air!$U$32 -> 67.507294 | P16: =[1]Air!$U$33 -> 64.455462 | Q16: =MAX(K16:P16) -> 67.56829 | R16: =AVERAGE(K16:P16) -> 63.976788
A17: 6 | B17: 45312 | C17: =[1]Air!$D$34 -> 7.6666667 | D17: =[1]Air!$D$35 -> 10.222222 | E17: =[1]Air!$D$36 -> 10.592105 | F17: =[1]Air!$D$37 -> 10.435185 | G17: =[1]Air!$D$48 -> 8.9444444 | H17: =[1]Air!$D$39 -> 11.180556 | I17: =MAX(C17:H17) -> 11.180556 | J17: =AVERAGE(C17:H17) -> 9.8401966 | K17: =[1]Air!$U$34 -> 50.015826 | L17: =[1]Air!$U$35 -> 58.696578 | M17: =[1]Air!$U$36 -> 56.726254 | N17: =[1]Air!$U$37 -> 53.01109 | O17: =[1]Air!$U$38 -> 62.508674 | P17: =[1]Air!$U$39 -> 50.722216 | Q17: =MAX(K17:P17) -> 62.508674 | R17: =AVERAGE(K17:P17) -> 55.280106
A18: 7 | B18: 45316 | C18: =[1]Air!$D$40 -> 10.861111 | D18: =[1]Air!$D$41 -> 12.710526 | E18: =[1]Air!$D$42 -> 12.745833 | F18: =[1]Air!$D$43 -> 11.925926 | G18: =[1]Air!$D$44 -> 12.671296 | H18: =[1]Air!$D$45 -> 11.180556 | I18: =MAX(C18:H18) -> 12.745833 | J18: =AVERAGE(C18:H18) -> 12.015875 | K18: =[1]Air!$U$40 -> 45.649995 | L18: =[1]Air!$U$41 -> 41.514293 | M18: =[1]Air!$U$42 -> 48.775428 | N18: =[1]Air!$U$43 -> 50.943835 | O18: =[1]Air!$U$44 -> 42.270207 | P18: =[1]Air!$U$45 -> 42.993009 | Q18: =MAX(K18:P18) -> 50.943835 | R18: =AVERAGE(K18:P18) -> 45.357794
A19: 8 | B19: 45319 | C19: =[1]Air!$D$46 -> 10.222222 | D19: =[1]Air!$D$47 -> 8.3055556 | E19: =[1]Air!$D$48 -> 8.9444444 | F19: =[1]Air!$D$49 -> 10.435185 | G19: =[1]Air!$D$50 -> 11.180556 | H19: =[1]Air!$D$51 -> 9.6898148 | I19: =MAX(C19:H19) -> 11.180556 | J19: =AVERAGE(C19:H19) -> 9.7962963 | K19: =[1]Air!$U$46 -> 38.783372 | L19: =[1]Air!$U$47 -> 40.156696 | M19: =[1]Air!$U$48 -> 43.715811 | N19: =[1]Air!$U$49 -> 44.438614 | O19: =[1]Air!$U$50 -> 48.433342 | P19: =[1]Air!$U$51 -> 48.775428 | Q19: =MAX(K19:P19) -> 48.775428 | R19: =AVERAGE(K19:P19) -> 44.050544
A24: Table B : Ambient Air Quality Data for RSPM and SPM under NAMP monitored by Walchand College of Engg., Sangli.
A25: Sampling Location: Udyoga Bhawan, Sangli.
A26: City : Sangli | G26: Month: January 2024
A27: State : Maharashtra | G27: NOTE: | H27: ALL PARAMETERS ARE IN µg/m3
A28: Station Type : Residential
A29: Code No. :- 574
A31: Sr No | B31: Date | C31: RSPM | F31: 8 hrs | G31: 24 hrs | H31: SPM | K31: 8 hrs | L31: 24 hrs | M31: Weather Cond.n | O31: Remarks
C32: 08--16 | D32: 16--24 | E32: 00--08 | F32: Max | G32: Avg | H32: 08--16 | I32: 16--24 | J32: 00-08 | K32: Max | L32: Avg | M32: Max | N32: Min
A33: 1 | B33: 45295 | C33: ='[2]SPM & RSPM'!$S$7 -> 120.37037 | D33: ='[2]SPM & RSPM'!$S$8 -> 116.00968 | E33: ='[2]SPM & RSPM'!$S$9 -> 158.41751 | F33: =MAX(C33:E33) -> 158.41751 | G33: =AVERAGE(C33:E33) -> 131.59919 | H33: ='[2]SPM & RSPM'!$T$7 -> 320.53872 | I33: ='[2]SPM & RSPM'!$T$8 -> 193.29184 | J33: ='[2]SPM & RSPM'!$T$9 -> 335.52189 | K33: =MAX(H33:J33) -> 335.52189 | L33: =AVERAGE(H33:J33) -> 283.11748
A34: 2 | B34: 45298 | C34: ='[2]SPM & RSPM'!$S$16 -> 130.92818 | D34: ='[2]SPM & RSPM'!$S$17 -> 53.353659 | E34: ='[2]SPM & RSPM'!$S$18 -> 81.144781 | F34: =MAX(C34:E34) -> 130.92818 | G34: =AVERAGE(C34:E34) -> 88.475541 | H34: ='[2]SPM & RSPM'!$T$16 -> 316.05691 | I34: ='[2]SPM & RSPM'!$T$17 -> 139.5664 | J34: ='[2]SPM & RSPM'!$T$18 -> 213.29966 | K34: =MAX(H34:J34) -> 316.05691 | L34: =AVERAGE(H34:J34) -> 222.97432
A35: 3 | B35: 45302 | C35: ='[2]SPM & RSPM'!$S$25 -> 113.31301 | D35: ='[2]SPM & RSPM'!$S$26 -> 159.09091 | E35: ='[2]SPM & RSPM'!$S$27 -> 62.244898 | F35: =MAX(C35:E35) -> 159.09091 | G35: =AVERAGE(C35:E35) -> 111.54961 | H35: ='[2]SPM & RSPM'!$T$25 -> 303.18428 | I35: ='[2]SPM & RSPM'!$T$26 -> 280.47521 | J35: ='[2]SPM & RSPM'!$T$27 -> 163.26531 | K35: =MAX(H35:J35) -> 303.18428 | L35: =AVERAGE(H35:J35) -> 248.97493
A36: 4 | B36: 45305 | C36: ='[2]SPM & RSPM'!$S$34 -> 121.27512 | D36: ='[2]SPM & RSPM'!$S$35 -> 144.93498 | E36: ='[2]SPM & RSPM'!$S$36 -> 187.37374 | F36: =MAX(C36:E36) -> 187.37374 | G36: =AVERAGE(C36:E36) -> 151.19461 | H36: ='[2]SPM & RSPM'!$T$34 -> 270.79002 | I36: ='[2]SPM & RSPM'!$T$35 -> 431.38261 | J36: ='[2]SPM & RSPM'!$T$36 -> 319.86532 | K36: =MAX(H36:J36) -> 431.38261 | L36: =AVERAGE(H36:J36) -> 340.67932
A37: 5 | B37: 45309 | C37: ='[2]SPM & RSPM'!$S$43 -> 172.38562 | D37: ='[2]SPM & RSPM'!$S$44 -> 124.91228 | E37: ='[2]SPM & RSPM'!$S$45 -> 165.95442 | F37: =MAX(C37:E37) -> 172.38562 | G37: =AVERAGE(C37:E37) -> 154.41744 | H37: ='[2]SPM & RSPM'!$T$43 -> 247.87582 | I37: ='[2]SPM & RSPM'!$T$44 -> 180.17544 | J37: ='[2]SPM & RSPM'!$T$45 -> 276.53134 | K37: =MAX(H37:J37) -> 276.53134 | L37: =AVERAGE(H37:J37) -> 234.86086
A38: 6 | B38: 45312 | C38: ='[2]SPM & RSPM'!$S$52 -> 143.43972 | D38: ='[2]SPM & RSPM'!$S$53 -> 132.57576 | E38: ='[2]SPM & RSPM'!$S$54 -> 139.12429 | F38: =MAX(C38:E38) -> 143.43972 | G38: =AVERAGE(C38:E38) -> 138.37992 | H38: ='[2]SPM & RSPM'!$T$52 -> 321.4539 | I38: ='[2]SPM & RSPM'!$T$53 -> 268.03752 | J38: ='[2]SPM & RSPM'!$T$54 -> 224.75282 | K38: =MAX(H38:J38) -> 321.4539 | L38: =AVERAGE(H38:J38) -> 271.41475
A39: 7 | B39: 45316 | C39: ='[2]SPM & RSPM'!$S$61 -> 110.53361 | D39: ='[2]SPM & RSPM'!$S$62 -> 99.686848 | E39: ='[2]SPM & RSPM'!$S$63 -> 184.4627 | F39: =MAX(C39:E39) -> 184.4627 | G39: =AVERAGE(C39:E39) -> 131.56105 | H39: ='[2]SPM & RSPM'!$T$61 -> 283.61053 | I39: ='[2]SPM & RSPM'!$T$62 -> 199.02575 | J39: ='[2]SPM & RSPM'!$T$63 -> 282.51198 | K39: =MAX(H39:J39) -> 283.61053 | L39: =AVERAGE(H39:J39) -> 255.04942
A40: 8 | B40: 45319 | C40: ='[2]SPM & RSPM'!$S$70 -> 82.276251 | D40: ='[2]SPM & RSPM'!$S$71 -> 107.14286 | E40: ='[2]SPM & RSPM'!$S$72 -> 89.057239 | F40: =MAX(C40:E40) -> 107.14286 | G40: =AVERAGE(C40:E40) -> 92.825449 | H40: ='[2]SPM & RSPM'!$T$70 -> 154.6864 | I40: ='[2]SPM & RSPM'!$T$71 -> 277.21088 | J40: ='[2]SPM & RSPM'!$T$72 -> 302.86195 | K40: =MAX(H40:J40) -> 302.86195 | L40: =AVERAGE(H40:J40) -> 244.91975
E45: SO2 | F45: NOX | G45: RSPM | H45: SPM
D46: n | E46: =COUNT(C12:H21) -> 48 | F46: =COUNT(K12:P21) -> 48 | G46: =COUNT(C33:E42) -> 24 | H46: =COUNT(H33:J42) -> 24
D47: AM | E47: =AVERAGE(C12:H21) -> 10.855367 | F47: =AVERAGE(K12:P21) -> 48.823658 | G47: =AVERAGE(C33:E42) -> 125.00035 | H47: =AVERAGE(H33:J42) -> 262.74885
D48: SD | E48: =STDEV(C12:H21) -> 1.5947227 | F48: =STDEV(K12:P21) -> 10.205779 | G48: =STDEV(C33:E42) -> 36.230454 | H48: =STDEV(H33:J42) -> 68.544141
D49: P | E49: =MAX(C12:H21) -> 14.907407 | F49: =MAXA(K12:P21) -> 68.291093 | G49: =MAXA(C33:E42) -> 187.37374 | H49: =MAXA(H33:J42) -> 431.38261
D50: GM | E50: =GEOMEAN(C12:H21) -> 10.738084 | F50: =GEOMEAN(K12:P21) -> 47.730152 | G50: =GEOMEAN(C33:E42) -> 119.35914 | H50: =GEOMEAN(H33:J42) -> 253.63883

Sheet Kupwad
A1: Table A : Ambient Air Quality Data for SO2 and NOx under NAMP monitored by Walchand College of Engg,. Sangli.
A2: Sampling Location : Kupwad,Sangli. | H2: Month: January 2024
A3: City : Sangli | L3: Parameter | N3: Unit
A4: State : Maharashtra | L4: SO2 | N4: µg/m3
A5: Station type: Industrial. | L5: NOx | N5: µg/m3
A6: Code No. :-576 | K6: am
A7: ** Monitoring could not be done due to power cut off or maintenance of machine
A10: Sr No | B10: Date | C10: SO2 | I10: 4 hrs | J10: 24 hrs | K10: NOx | Q10: 4 hrs | R10: 24 hrs | S10: Weather Cond.n
C11: 08--12 | D11: 12--16 | E11: 16--20 | F11: 20--24 | G11: 00-04 | H11: 04--08 | I11: Max | J11: Avg | K11: 08--12 | L11: 12--16 | M11: 16--20 | N11: 20--24 | O11: 00-04 | P11: 04--08 | Q11: Max. | R11: Avg | S11: Max | T11: Min
A12: 1 | B12: 45292 | C12: =[1]Air!$I$4 -> 14.122807 | D12: =[1]Air!$I$5 -> 14.162037 | E12: =[1]Air!$I$6 -> 14.907407 | F12: =[1]Air!$I$7 -> 15.652778 | G12: =[1]Air!$I$8 -> 10.435185 | H12: =[1]Air!$I$9 -> 11.298246 | I12: =MAX(C12:H12) -> 15.652778 | J12: =AVERAGE(C12:H12) -> 13.429743 | K12: =[1]Air!$AA$4 -> 60.340266 | L12: =[1]Air!$AA$5 -> 66.744336 | M12: =[1]Air!$AA$6 -> 68.270252 | N12: =[1]Air!$AA$7 -> 59.617464 | O12: =[1]Air!$AA$8 -> 57.449057 | P12: =[1]Air!$AA$9 -> 69.736698 | Q12: =MAX(K12:P12) -> 69.736698 | R12: =AVERAGE(K12:P12) -> 63.693012
A13: 2 | B13: 45296 | C13: =[1]Air!$I$10 -> 13.416667 | D13: =[1]Air!$I$11 -> 14.162037 | E13: =[1]Air!$I$12 -> 15.652778 | F13: =[1]Air!$I$13 -> 17.143519 | G13: =[1]Air!$I$14 -> 17.653509 | H13: =[1]Air!$I$15 -> 14.828947 | I13: =MAX(C13:H13) -> 17.653509 | J13: =AVERAGE(C13:H13) -> 15.476243 | K13: =[1]Air!$AA$10 -> 56.726254 | L13: =[1]Air!$AA$11 -> 53.835045 | M13: =[1]Air!$AA$12 -> 65.981378 | N13: =[1]Air!$AA$13 -> 45.38151 | O13: =[1]Air!$AA$14 -> 66.744336 | P13: =[1]Air!$AA$15 -> 61.785871 | Q13: =MAX(K13:P13) -> 66.744336 | R13: =AVERAGE(K13:P13) -> 58.409066
A14: 3 | B14: 45299 | C14: =[1]Air!$I$16 -> 14.907407 | D14: =[1]Air!$I$17 -> 11.298246 | E14: =[1]Air!$I$18 -> 11.180556 | F14: =[1]Air!$I$19 -> 10.592105 | G14: =[1]Air!$I$20 -> 10.435185 | H14: =[1]Air!$I$21 -> 12.671296 | I14: =MAX(C14:H14) -> 14.907407 | J14: =AVERAGE(C14:H14) -> 11.847466 | K14: =[1]Air!$AA$16 -> 38.656195 | L14: =[1]Air!$AA$17 -> 43.855593 | M14: =[1]Air!$AA$18 -> 37.933392 | N14: =[1]Air!$AA$19 -> 46.607021 | O14: =[1]Air!$AA$20 -> 63.692503 | P14: =[1]Air!$AA$21 -> 61.403629 | Q14: =MAX(K14:P14) -> 63.692503 | R14: =AVERAGE(K14:P14) -> 48.691389
A15: 4 | B15: 45303 | C15: =[1]Air!$I$22 -> 11.298246 | D15: =[1]Air!$I$23 -> 7.4537037 | E15: =[1]Air!$I$24 -> 17.143519 | F15: =[1]Air!$I$25 -> 15.652778 | G15: =[1]Air!$I$26 -> 18.634259 | H15: =[1]Air!$I$27 -> 14.907407 | I15: =MAX(C15:H15) -> 18.634259 | J15: =AVERAGE(C15:H15) -> 14.181652 | K15: =[1]Air!$AA$22 -> 72.627907 | L15: =[1]Air!$AA$23 -> 59.617464 | M15: =[1]Air!$AA$24 -> 57.449057 | N15: =[1]Air!$AA$25 -> 67.56829 | O15: =[1]Air!$AA$26 -> 61.785871 | P15: =[1]Air!$AA$27 -> 62.508674 | Q15: =MAX(K15:P15) -> 72.627907 | R15: =AVERAGE(K15:P15) -> 63.592877
A16: 5 | B16: 45306 | C16: =[1]Air!$I$28 -> 14.828947 | D16: =[1]Air!$I$29 -> 15.535088 | E16: =[1]Air!$I$30 -> 14.828947 | F16: =[1]Air!$I$31 -> 12.710526 | G16: =[1]Air!$I$32 -> 13.416667 | H16: =[1]Air!$I$33 -> 12.004386 | I16: =MAX(C16:H16) -> 15.535088 | J16: =AVERAGE(C16:H16) -> 13.887427 | K16: =[1]Air!$AA$28 -> 54.557847 | L16: =[1]Air!$AA$29 -> 53.835045 | M16: =[1]Air!$AA$30 -> 56.726254 | N16: =[1]Air!$AA$31 -> 47.329823 | O16: =[1]Air!$AA$32 -> 59.617464 | P16: =[1]Air!$AA$33 -> 60.340266 | Q16: =MAX(K16:P16) -> 60.340266 | R16: =AVERAGE(K16:P16) -> 55.401117
A17: 6 | B17: 45310 | C17: =[1]Air!$I$34 -> 14.907407 | D17: =[1]Air!$I$35 -> 13.416667 | E17: =[1]Air!$I$36 -> 12.671296 | F17: =[1]Air!$I$37 -> 12.710526 | G17: =[1]Air!$I$38 -> 11.298246 | H17: =[1]Air!$I$39 -> 12.004386 | I17: =MAX(C17:H17) -> 14.907407 | J17: =AVERAGE(C17:H17) -> 12.834755 | K17: =[1]Air!$AA$34 -> 63.954278 | L17: =[1]Air!$AA$35 -> 62.508674 | M17: =[1]Air!$AA$36 -> 61.785871 | N17: =[1]Air!$AA$37 -> 66.122686 | O17: =[1]Air!$AA$38 -> 81.301536 | P17: =[1]Air!$AA$39 -> 82.747141 | Q17: =MAX(K17:P17) -> 82.747141 | R17: =AVERAGE(K17:P17) -> 69.736698
A18: 7 | B18: 45313 | C18: =[1]Air!$I$40 -> 10.435185 | D18: =[1]Air!$I$41 -> 9.1798246 | E18: =[1]Air!$I$42 -> 10.592105 | F18: =[1]Air!$I$43 -> 10.435185 | G18: =[1]Air!$I$44 -> 11.925926 | H18: =[1]Air!$I$45 -> 9.1798246 | I18: =MAX(C18:H18) -> 11.925926 | J18: =AVERAGE(C18:H18) -> 10.291342 | K18: =[1]Air!$AA$40 -> 59.877713 | L18: =[1]Air!$AA$41 -> 57.449057 | M18: =[1]Air!$AA$42 -> 61.785871 | N18: =[1]Air!$AA$43 -> 69.796168 | O18: =[1]Air!$AA$44 -> 61.403629 | P18: =[1]Air!$AA$45 -> 62.508674 | Q18: =MAX(K18:P18) -> 69.796168 | R18: =AVERAGE(K18:P18) -> 62.136852
A19: 8 | B19: 45317 | C19: =[1]Air!$I$46 -> 11.925926 | D19: =[1]Air!$I$47 -> 10.592105 | E19: =[1]Air!$I$48 -> 9.8859649 | F19: =[1]Air!$I$49 -> 13.416667 | G19: =[1]Air!$I$50 -> 9.1798246 | H19: =[1]Air!$I$51 -> 9.8859649 | I19: =MAX(C19:H19) -> 13.416667 | J19: =AVERAGE(C19:H19) -> 10.814409 | K19: =[1]Air!$AA$46 -> 58.894662 | L19: =[1]Air!$AA$47 -> 57.449057 | M19: =[1]Air!$AA$48 -> 54.557847 | N19: =[1]Air!$AA$49 -> 59.877713 | O19: =[1]Air!$AA$50 -> 59.617464 | P19: =[1]Air!$AA$51 -> 62.508674 | Q19: =MAX(K19:P19) -> 62.508674 | R19: =AVERAGE(K19:P19) -> 58.817569
A20: 9 | B20: 45320 | C20: =[1]Air!$I$52 -> 10.592105 | D20: =[1]Air!$I$53 -> 11.298246 | E20: =[1]Air!$I$54 -> 14.122807 | F20: =[1]Air!$I$55 -> 9.8859649 | G20: =[1]Air!$I$56 -> 16.241228 | H20: =[1]Air!$I$57 -> 14.828947 | I20: =MAX(C20:H20) -> 16.241228 | J20: =AVERAGE(C20:H20) -> 12.828216 | K20: =[1]Air!$AA$52 -> 58.171859 | L20: =[1]Air!$AA$53 -> 57.449057 | M20: =[1]Air!$AA$54 -> 62.508674 | N20: =[1]Air!$AA$55 -> 73.610959 | O20: =[1]Air!$AA$56 -> 63.954278 | P20: =[1]Air!$AA$57 -> 58.894662 | Q20: =MAX(K20:P20) -> 73.610959 | R20: =AVERAGE(K20:P20) -> 62.431581
A24: Table B : Ambient Air Quality Data for RSPM and SPM under NAMP monitored by Walchand College of Engg., Sangli.
A25: Sampling Location : Kupwad,Sangli. | H25: Month: January 2024
A26: City : Sangli
A27: State : Maharashtra | H27: NOTE: | I27: ALL PARAMETERS ARE IN µg/m3
A28: Station type: Industrial.
A29: Code No. :-576
B31: Date | C31: RSPM | F31: 8 hrs | G31: 24 hrs | H31: SPM | K31: 8 hrs | L31: 24 hrs | M31: Weather Cond.n | O31: Remark
A32: Sr No | C32: 08--16 | D32: 16--24 | E32: 00-08 | F32: Max | G32: Avg | H32: 08--16 | I32: 16--24 | J32: 00-08 | K32: Max | L32: Avg | M32: Max. | N32: Min.
A33: 1 | B33: 45292 | C33: ='[2]SPM & RSPM'!$S$10 -> 145.91978 | D33: ='[2]SPM & RSPM'!$S$11 -> 145.61767 | E33: ='[2]SPM & RSPM'!$S$12 -> 201.82556 | F33: =MAX(C33:E33) -> 201.82556 | G33: =AVERAGE(C33:E33) -> 164.45433 | H33: ='[2]SPM & RSPM'!$T$10 -> 177.73167 | I33: ='[2]SPM & RSPM'!$T$11 -> 275.01725 | J33: ='[2]SPM & RSPM'!$T$12 -> 392.49493 | K33: =MAX(H33:J33) -> 392.49493 | L33: =AVERAGE(H33:J33) -> 281.74795
A34: 2 | B34: 45296 | C34: ='[2]SPM & RSPM'!$S$19 -> 132.2832 | D34: ='[2]SPM & RSPM'!$S$20 -> 142.95393 | E34: ='[2]SPM & RSPM'!$S$21 -> 49.070248 | F34: =MAX(C34:E34) -> 142.95393 | G34: =AVERAGE(C34:E34) -> 108.10246 | H34: ='[2]SPM & RSPM'!$T$19 -> 372.96748 | I34: ='[2]SPM & RSPM'!$T$20 -> 153.62466 | J34: ='[2]SPM & RSPM'!$T$21 -> 151.8595 | K34: =MAX(H34:J34) -> 372.96748 | L34: =AVERAGE(H34:J34) -> 226.15055
A35: 3 | B35: 45299 | C35: ='[2]SPM & RSPM'!$S$28 -> 91.065292 | D35: ='[2]SPM & RSPM'!$S$29 -> 82.65167 | E35: ='[2]SPM & RSPM'!$S$30 -> 141.50607 | F35: =MAX(C35:E35) -> 141.50607 | G35: =AVERAGE(C35:E35) -> 105.07434 | H35: ='[2]SPM & RSPM'!$T$28 -> 204.29553 | I35: ='[2]SPM & RSPM'!$T$29 -> 523.6878 | J35: ='[2]SPM & RSPM'!$T$30 -> 299.07209 | K35: =MAX(H35:J35) -> 523.6878 | L35: =AVERAGE(H35:J35) -> 342.35181
A36: 4 | B36: 45303 | C36: ='[2]SPM & RSPM'!$S$37 -> 113.52401 | D36: ='[2]SPM & RSPM'!$S$38 -> 109.63115 | E36: ='[2]SPM & RSPM'!$S$39 -> 168.97163 | F36: =MAX(C36:E36) -> 168.97163 | G36: =AVERAGE(C36:E36) -> 130.70893 | H36: ='[2]SPM & RSPM'!$T$37 -> 145.83333 | I36: ='[2]SPM & RSPM'!$T$38 -> 307.88934 | J36: ='[2]SPM & RSPM'!$T$39 -> 194.14894 | K36: =MAX(H36:J36) -> 307.88934 | L36: =AVERAGE(H36:J36) -> 215.9572
A37: 5 | B37: 45306 | C37: ='[2]SPM & RSPM'!$S$46 -> 137.56064 | D37: ='[2]SPM & RSPM'!$S$47 -> 110.46919 | E37: ='[2]SPM & RSPM'!$S$48 -> 250.41667 | F37: =MAX(C37:E37) -> 250.41667 | G37: =AVERAGE(C37:E37) -> 166.14883 | H37: ='[2]SPM & RSPM'!$T$46 -> 334.71933 | I37: ='[2]SPM & RSPM'!$T$47 -> 360.64426 | J37: ='[2]SPM & RSPM'!$T$48 -> 398.95833 | K37: =MAX(H37:J37) -> 398.95833 | L37: =AVERAGE(H37:J37) -> 364.77398
A38: 6 | B38: 45310 | C38: ='[2]SPM & RSPM'!$S$55 -> 155.54379 | D38: ='[2]SPM & RSPM'!$S$56 -> 87.284483 | E38: ='[2]SPM & RSPM'!$S$57 -> 190.14831 | F38: =MAX(C38:E38) -> 190.14831 | G38: =AVERAGE(C38:E38) -> 144.32552 | H38: ='[2]SPM & RSPM'!$T$55 -> 200.56497 | I38: ='[2]SPM & RSPM'!$T$56 -> 267.42098 | J38: ='[2]SPM & RSPM'!$T$57 -> 482.16808 | K38: =MAX(H38:J38) -> 482.16808 | L38: =AVERAGE(H38:J38) -> 316.71801
A39: 7 | B39: 45313 | C39: ='[2]SPM & RSPM'!$S$64 -> 108.65191 | D39: ='[2]SPM & RSPM'!$S$65 -> 99.164927 | E39: ='[2]SPM & RSPM'!$S$66 -> 167.02052 | F39: =MAX(C39:E39) -> 167.02052 | G39: =AVERAGE(C39:E39) -> 124.94579 | H39: ='[2]SPM & RSPM'!$T$64 -> 275.98927 | I39: ='[2]SPM & RSPM'!$T$65 -> 102.47042 | J39: ='[2]SPM & RSPM'!$T$66 -> 208.59873 | K39: =MAX(H39:J39) -> 275.98927 | L39: =AVERAGE(H39:J39) -> 195.68614
A40: 8 | B40: 45317 | C40: ='[2]SPM & RSPM'!$S$73 -> 104.20842 | D40: ='[2]SPM & RSPM'!$S$74 -> 85.223368 | E40: ='[2]SPM & RSPM'!$S$75 -> 115.30612 | F40: =MAX(C40:E40) -> 115.30612 | G40: =AVERAGE(C40:E40) -> 101.5793 | H40: ='[2]SPM & RSPM'!$T$73 -> 184.03474 | I40: ='[2]SPM & RSPM'!$T$74 -> 186.2543 | J40: ='[2]SPM & RSPM'!$T$75 -> 250.68027 | K40: =MAX(H40:J40) -> 250.68027 | L40: =AVERAGE(H40:J40) -> 206.98977
A41: 9 | B41: 45320 | C41: ='[2]SPM & RSPM'!$S$82 -> 83.521021 | D41: ='[2]SPM & RSPM'!$S$83 -> 102.92023 | E41: ='[2]SPM & RSPM'!$S$84 -> 125.60891 | F41: =MAX(C41:E41) -> 125.60891 | G41: =AVERAGE(C41:E41) -> 104.01672 | H41: ='[2]SPM & RSPM'!$T$82 -> 166.47898 | I41: ='[2]SPM & RSPM'!$T$83 -> 128.73932 | J41: ='[2]SPM & RSPM'!$T$84 -> 302.01809 | K41: =MAX(H41:J41) -> 302.01809 | L41: =AVERAGE(H41:J41) -> 199.0788
E44: SO2 | F44: NOX | G44: RSPM | H44: SPM
D45: n | E45: =COUNT(C12:H21) -> 54 | F45: =COUNT(K12:P21) -> 54 | G45: =COUNT(C33:E42) -> 27 | H45: =COUNT(H33:J42) -> 27
D46: AM | E46: =AVERAGE(C12:H21) -> 12.843472 | F46: =AVERAGE(K12:P21) -> 60.323351 | G46: =AVERAGE(C33:E42) -> 127.70625 | H46: =AVERAGE(H33:J42) -> 261.05047
D47: SD | E47: =STDEV(C12:H21) -> 2.5100205 | F47: =STDEV(K12:P21) -> 8.5081632 | G47: =STDEV(C33:E39) -> 45.71461 | H47: =STDEV(H33:J39) -> 114.73917
D48: P | E48: =MAX(C12:H21) -> 18.634259 | F48: =MAXA(K12:P21) -> 82.747141 | G48: =MAXA(C33:E42) -> 250.41667 | H48: =MAXA(H33:J42) -> 523.6878
...

Sheet Rajawada Chowk
A1: Table A : Ambient Air Quality Data for SO2 and NOx under NAMP monitored by Walchand College of Engg., Sangli.
A2: Sampling Location :Terrace of Municipal School,Rajawada Chowk,Sangli.
A3: City : Sangli. | K3: Parameter | M3: Unit
A4: State : Maharashtra | G4: Month: January 2024 | K4: SO2 | M4: µg/m3
A5: Station type: commercial | K5: NOx | M5: µg/m3
A6: Code No. :-575 | K6: am
A7: ** Monitoring could not be done due to power cut off or maintenance of machine
A10: Sr No | B10: Date | C10: SO2 | I10: 4 hrs | J10: 24 hrs | K10: NOx | Q10: 4 hrs | R10: 24 hrs | S10: Weather Cond.n | U10: Remark
B11: Date | C11: 08--12 | D11: 12--16 | E11: 16--20 | F11: 20--24 | G11: 00-04 | H11: 04--08 | I11: Max | J11: Avg | K11: 08--12 | L11: 12--16 | M11: 16--20 | N11: 20--24 | O11: 00-04 | P11: 04--08 | Q11: Max | R11: Avg | S11: Max | T11: Min
A12: 1 | B12: 45294 | C12: =[1]Air!$N$4 -> 17.653509 | D12: =[1]Air!$N$5 -> 10.733333 | E12: =[1]Air!$N$6 -> 10.592105 | F12: =[1]Air!$N$7 -> 10.435185 | G12: =[1]Air!$N$8 -> 13.416667 | H12: =[1]Air!$N$9 -> 14.122807 | I12: =MAX(C12:H12) -> 17.653509 | J12: =AVERAGE(C12:H12) -> 12.825601 | K12: =[1]Air!$AG$4 -> 57.588839 | L12: =[1]Air!$AG$5 -> 56.726254 | M12: =[1]Air!$AG$6 -> 56.825881 | N12: =[1]Air!$AG$7 -> 60.640671 | O12: =[1]Air!$AG$8 -> 61.785871 | P12: =[1]Air!$AG$9 -> 58.351797 | Q12: =MAX(K12:P12) -> 61.785871 | R12: =AVERAGE(K12:P12) -> 58.653219
A13: 2 | B13: 45297 | C13: =[1]Air!$N$10 -> 9.3916667 | D13: =[1]Air!$N$11 -> 11.157018 | E13: =[1]Air!$N$12 -> 13.416667 | F13: =[1]Air!$N$13 -> 16.241228 | G13: =[1]Air!$N$14 -> 14.828947 | H13: =[1]Air!$N$15 -> 17.143519 | I13: =MAX(C13:H13) -> 17.143519 | J13: =AVERAGE(C13:H13) -> 13.696507 | K13: =[1]Air!$AG$10 -> 59.877713 | L13: =[1]Air!$AG$11 -> 57.449057 | M13: =[1]Air!$AG$12 -> 64.455462 | N13: =[1]Air!$AG$13 -> 61.785871 | O13: =[1]Air!$AG$14 -> 69.736698 | P13: =[1]Air!$AG$15 -> 61.785871 | Q13: =MAX(K13:P13) -> 69.736698 | R13: =AVERAGE(K13:P13) -> 62.515112
A14: 3 | B14: 45301 | C14: =[1]Air!$N$16 -> 16.947368 | D14: =[1]Air!$N$17 -> 16.770833 | E14: =[1]Air!$N$18 -> 16.241228 | F14: =[1]Air!$N$19 -> 15.652778 | G14: =[1]Air!$N$20 -> 18.634259 | H14: =[1]Air!$N$21 -> 14.907407 | I14: =MAX(C14:H14) -> 18.634259 | J14: =AVERAGE(C14:H14) -> 16.525646 | K14: =[1]Air!$AG$16 -> 67.56829 | L14: =[1]Air!$AG$17 -> 70.4595 | M14: =[1]Air!$AG$18 -> 62.508674 | N14: =[1]Air!$AG$19 -> 59.877713 | O14: =[1]Air!$AG$20 -> 67.507294 | P14: =[1]Air!$AG$21 -> 65.21842 | Q14: =MAX(K14:P14) -> 70.4595 | R14: =AVERAGE(K14:P14) -> 65.523315
A15: 4 | B15: 45304 | C15: =[1]Air!$N$22 -> 14.828947 | D15: =[1]Air!$N$23 -> 12.075 | E15: =[1]Air!$N$24 -> 13.416667 | F15: =[1]Air!$N$25 -> 12.671296 | G15: =[1]Air!$N$26 -> 11.925926 | H15: =[1]Air!$N$27 -> 9.6898148 | I15: =MAX(C15:H15) -> 14.828947 | J15: =AVERAGE(C15:H15) -> 12.434609 | K15: =[1]Air!$AG$22 -> 62.508674 | L15: =[1]Air!$AG$23 -> 64.455462 | M15: =[1]Air!$AG$24 -> 64.677081 | N15: =[1]Air!$AG$25 -> 74.373917 | O15: =[1]Air!$AG$26 -> 69.03321 | P15: =[1]Air!$AG$27 -> 66.122686 | Q15: =MAX(K15:P15) -> 74.373917 | R15: =AVERAGE(K15:P15) -> 66.861838
A16: 5 | B16: 45308 | C16: =[1]Air!$N$28 -> 9.8859649 | D16: =[1]Air!$N$29 -> 12.075 | E16: =[1]Air!$N$30 -> 14.122807 | F16: =[1]Air!$N$31 -> 13.416667 | G16: =[1]Air!$N$32 -> 16.398148 | H16: =[1]Air!$N$33 -> 14.122807 | I16: =MAX(C16:H16) -> 16.398148 | J16: =AVERAGE(C16:H16) -> 13.336899 | K16: =[1]Air!$AG$28 -> 71.182302 | L16: =[1]Air!$AG$29 -> 69.736698 | M16: =[1]Air!$AG$30 -> 84.292372 | N16: =[1]Air!$AG$31 -> 78.188707 | O16: =[1]Air!$AG$32 -> 78.951665 | P16: =[1]Air!$AG$33 -> 64.677081 | Q16: =MAX(K16:P16) -> 84.292372 | R16: =AVERAGE(K16:P16) -> 74.504804
A17: 6 | B17: 45311 | C17: =[1]Air!$N$34 -> 10.592105 | D17: =[1]Air!$N$35 -> 9.1798246 | E17: =[1]Air!$N$36 -> 9.3916667 | F17: =[1]Air!$N$37 -> 11.298246 | G17: =[1]Air!$N$38 -> 10.592105 | H17: =[1]Air!$N$39 -> 9.3916667 | I17: =MAX(C17:H17) -> 11.298246 | J17: =AVERAGE(C17:H17) -> 10.074269 | K17: =[1]Air!$AG$34 -> 61.063069 | L17: =[1]Air!$AG$35 -> 66.744336 | M17: =[1]Air!$AG$36 -> 59.617464 | N17: =[1]Air!$AG$37 -> 60.640671 | O17: =[1]Air!$AG$38 -> 79.714623 | P17: =[1]Air!$AG$39 -> 76.964721 | Q17: =MAX(K17:P17) -> 79.714623 | R17: =AVERAGE(K17:P17) -> 67.457481
A18: 7 | B18: 45315 | C18: =[1]Air!$N$40 -> 13.416667 | D18: =[1]Air!$N$41 -> 13.416667 | E18: =[1]Air!$N$42 -> 17.143519 | F18: =[1]Air!$N$43 -> 16.947368 | G18: =[1]Air!$N$44 -> 15.535088 | H18: =[1]Air!$N$45 -> 14.907407 | I18: =MAX(C18:H18) -> 17.143519 | J18: =AVERAGE(C18:H18) -> 15.227786 | K18: =[1]Air!$AG$40 -> 65.21842 | L18: =[1]Air!$AG$41 -> 81.301536 | M18: =[1]Air!$AG$42 -> 63.231476 | N18: =[1]Air!$AG$43 -> 64.677081 | O18: =[1]Air!$AG$44 -> 74.073512 | P18: =[1]Air!$AG$45 -> 85.05533 | Q18: =MAX(K18:P18) -> 85.05533 | R18: =AVERAGE(K18:P18) -> 72.259559
A19: 8 | B19: 45318 | C19: =[1]Air!$N$46 -> 13.416667 | D19: =[1]Air!$N$47 -> 12.075 | E19: =[1]Air!$N$48 -> 11.404167 | F19: =[1]Air!$N$49 -> 10.733333 | G19: =[1]Air!$N$50 -> 12.075 | H19: =[1]Air!$N$51 -> 14.122807 | I19: =MAX(C19:H19) -> 14.122807 | J19: =AVERAGE(C19:H19) -> 12.304496 | K19: =[1]Air!$AG$46 -> 65.399883 | L19: =[1]Air!$AG$47 -> 63.231476 | M19: =[1]Air!$AG$48 -> 54.557847 | N19: =[1]Air!$AG$49 -> 57.449057 | O19: =[1]Air!$AG$50 -> 58.171859 | P19: =[1]Air!$AG$51 -> 60.340266 | Q19: =MAX(K19:P19) -> 65.399883 | R19: =AVERAGE(K19:P19) -> 59.858398
A20: 9 | B20: 45322 | C20: =[1]Air!$N$52 -> 10.733333 | D20: =[1]Air!$N$53 -> 12.710526 | E20: =[1]Air!$N$54 -> 13.416667 | F20: =[1]Air!$N$55 -> 12.710526 | G20: =[1]Air!$N$56 -> 12.004386 | H20: =[1]Air!$N$57 -> 13.416667 | I20: =MAX(C20:H20) -> 13.416667 | J20: =AVERAGE(C20:H20) -> 12.498684 | K20: =[1]Air!$AG$52 -> 42.270207 | L20: =[1]Air!$AG$53 -> 47.670384 | M20: =[1]Air!$AG$54 -> 48.775428 | N20: =[1]Air!$AG$55 -> 56.825881 | O20: =[1]Air!$AG$56 -> 55.299965 | P20: =[1]Air!$AG$57 -> 53.835045 | Q20: =MAX(K20:P20) -> 56.825881 | R20: =AVERAGE(K20:P20) -> 50.779485
A24: Table B : Ambient Air Quality Data for RSPM and SPM under NAMP monitored by Walchand College of Engg., Sangli.
A25: Sampling Location :Terrace of Municipal School, Rajawada Chowk,Sangli.
A26: City : Sangli. | G26: Month: January 2024
A27: State : Maharashtra | G27: NOTE: | H27: ALL PARAMETERS ARE IN µg/m3
A28: Station type: commercial
A29: Code No. :-575
A31: Sr No | B31: Date | C31: RSPM | F31: 8 hrs | G31: 24 hrs | H31: SPM | K31: 8 hrs | L31: 24 hrs | M31: Weather Cond.n | O31: Remark
C32: 08--16 | D32: 16--24 | E32: 00-08 | F32: Max | G32: Avg | H32: 08--16 | I32: 16--24 | J32: 00-08 | K32: Max | L32: Avg | M32: Max | N32: Min
A33: 1 | B33: 45294 | C33: ='[2]SPM & RSPM'!$S$13 -> 28.219697 | D33: ='[2]SPM & RSPM'!$S$14 -> 146.2585 | E33: ='[2]SPM & RSPM'!$S$15 -> 149.05303 | F33: =MAX(C33:E33) -> 149.05303 | G33: =AVERAGE(C33:E33) -> 107.84374 | H33: ='[2]SPM & RSPM'!$T$13 -> 276.13636 | I33: ='[2]SPM & RSPM'!$T$14 -> 217.87604 | J33: ='[2]SPM & RSPM'!$T$15 -> 263.44697 | K33: =MAX(H33:J33) -> 276.13636 | L33: =AVERAGE(H33:J33) -> 252.48646
A34: 2 | B34: 45297 | C34: ='[2]SPM & RSPM'!$S$22 -> 140.95345 | D34: ='[2]SPM & RSPM'!$S$23 -> 115.90909 | E34: ='[2]SPM & RSPM'!$S$24 -> 140.09112 | F34: =MAX(C34:E34) -> 140.95345 | G34: =AVERAGE(C34:E34) -> 132.31789 | H34: ='[2]SPM & RSPM'!$T$22 -> 241.36637 | I34: ='[2]SPM & RSPM'!$T$23 -> 184.4697 | J34: ='[2]SPM & RSPM'!$T$24 -> 173.12073 | K34: =MAX(H34:J34) -> 241.36637 | L34: =AVERAGE(H34:J34) -> 199.65226
A35: 3 | B35: 45301 | C35: ='[2]SPM & RSPM'!$S$31 -> 142.42424 | D35: ='[2]SPM & RSPM'!$S$32 -> 134.96583 | E35: ='[2]SPM & RSPM'!$S$33 -> 133.02752 | F35: =MAX(C35:E35) -> 142.42424 | G35: =AVERAGE(C35:E35) -> 136.80587 | H35: ='[2]SPM & RSPM'!$T$31 -> 320.26515 | I35: ='[2]SPM & RSPM'!$T$32 -> 172.55125 | J35: ='[2]SPM & RSPM'!$T$33 -> 180.04587 | K35: =MAX(H35:J35) -> 320.26515 | L35: =AVERAGE(H35:J35) -> 224.28743
A36: 4 | B36: 45304 | C36: ='[2]SPM & RSPM'!$S$40 -> 161.28434 | D36: ='[2]SPM & RSPM'!$S$41 -> 110.48265 | E36: ='[2]SPM & RSPM'!$S$42 -> 111.42749 | F36: =MAX(C36:E36) -> 161.28434 | G36: =AVERAGE(C36:E36) -> 127.73149 | H36: ='[2]SPM & RSPM'!$T$40 -> 219.74759 | I36: ='[2]SPM & RSPM'!$T$41 -> 168.3635 | J36: ='[2]SPM & RSPM'!$T$42 -> 154.13819 | K36: =MAX(H36:J36) -> 219.74759 | L36: =AVERAGE(H36:J36) -> 180.74976
A37: 5 | B37: 45308 | C37: ='[2]SPM & RSPM'!$S$49 -> 119.04762 | D37: ='[2]SPM & RSPM'!$S$50 -> 109.18899 | E37: ='[2]SPM & RSPM'!$S$51 -> 99.752825 | F37: =MAX(C37:E37) -> 119.04762 | G37: =AVERAGE(C37:E37) -> 109.32981 | H37: ='[2]SPM & RSPM'!$T$49 -> 355.28274 | I37: ='[2]SPM & RSPM'!$T$50 -> 198.4747 | J37: ='[2]SPM & RSPM'!$T$51 -> 138.94774 | K37: =MAX(H37:J37) -> 355.28274 | L37: =AVERAGE(H37:J37) -> 230.90173
A38: 6 | B38: 45311 | C38: ='[2]SPM & RSPM'!$S$58 -> 104.49146 | D38: ='[2]SPM & RSPM'!$S$59 -> 99.547511 | E38: ='[2]SPM & RSPM'!$S$60 -> 162.53444 | F38: =MAX(C38:E38) -> 162.53444 | G38: =AVERAGE(C38:E38) -> 122.19114 | H38: ='[2]SPM & RSPM'!$T$58 -> 242.76169 | I38: ='[2]SPM & RSPM'!$T$59 -> 241.13876 | J38: ='[2]SPM & RSPM'!$T$60 -> 232.09366 | K38: =MAX(H38:J38) -> 242.76169 | L38: =AVERAGE(H38:J38) -> 238.66471
A39: 7 | B39: 45315 | C39: ='[2]SPM & RSPM'!$S$67 -> 91.463415 | D39: ='[2]SPM & RSPM'!$S$68 -> 113.17568 | E39: ='[2]SPM & RSPM'!$S$69 -> 126.04404 | F39: =MAX(C39:E39) -> 126.04404 | G39: =AVERAGE(C39:E39) -> 110.22771 | H39: ='[2]SPM & RSPM'!$T$67 -> 203.25203 | I39: ='[2]SPM & RSPM'!$T$68 -> 240.24024 | J39: ='[2]SPM & RSPM'!$T$69 -> 160.2126 | K39: =MAX(H39:J39) -> 240.24024 | L39: =AVERAGE(H39:J39) -> 201.23496
A40: 8 | B40: 45318 | C40: ='[2]SPM & RSPM'!$S$76 -> 93.939394 | D40: ='[2]SPM & RSPM'!$S$77 -> 109.98498 | E40: ='[2]SPM & RSPM'!$S$78 -> 148.9842 | F40: =MAX(C40:E40) -> 148.9842 | G40: =AVERAGE(C40:E40) -> 117.63619 | H40: ='[2]SPM & RSPM'!$T$76 -> 360.79545 | I40: ='[2]SPM & RSPM'!$T$77 -> 243.99399 | J40: ='[2]SPM & RSPM'!$T$78 -> 205.04138 | K40: =MAX(H40:J40) -> 360.79545 | L40: =AVERAGE(H40:J40) -> 269.94361
A41: 9 | B41: 45322 | C41: ='[2]SPM & RSPM'!$S$85 -> 79.545455 | D41: ='[2]SPM & RSPM'!$S$86 -> 94.69697 | E41: ='[2]SPM & RSPM'!$S$87 -> 123.5119 | F41: =MAX(C41:E41) -> 123.5119 | G41: =AVERAGE(C41:E41) -> 99.251443 | H41: ='[2]SPM & RSPM'!$T$85 -> 202.65152 | I41: ='[2]SPM & RSPM'!$T$86 -> 119.12879 | J41: ='[2]SPM & RSPM'!$T$87 -> 344.86607 | K41: =MAX(H41:J41) -> 344.86607 | L41: =AVERAGE(H41:J41) -> 222.21546
E45: SO2 | F45: NOX | G45: RSPM | H45: SPM
D46: n | E46: =COUNT(C12:H21) -> 54 | F46: =COUNT(K12:P21) -> 54 | G46: =COUNT(C33:E42) -> 27 | H46: =COUNT(D33:F42) -> 27
D47: AM | E47: =AVERAGE(C12:H21) -> 13.213833 | F47: =AVERAGE(K12:P21) -> 64.268135 | G47: =AVERAGE(C33:E42) -> 118.14836 | H47: =AVERAGE(H33:J42) -> 224.4596
D48: SD | E48: =STDEV(C12:H21) -> 2.4786692 | F48: =STDEV(K12:P21) -> 8.8311023 | G48: =STDEV(C33:E42) -> 28.616116 | H48: =STDEV(H33:J42) -> 64.069824
D49: P | E49: =MAX(C12:H21) -> 18.634259 | F49: =MAXA(K12:P21) -> 85.05533 | G49: =MAXA(C33:E42) -> 162.53444 | H49: =MAXA(H33:J42) -> 360.79545
...

Sheet Monthly Data Sheet
A1: TABLE C: Monthly Data Sheet for NAMP Project
A2: Name of the city : Sangli
A3: Month: January 2024
A4: Sampling Point | B4: Station Code | C4: Month | D4: Year | E4: SO2 µg/m3 | I4: NOx µg/m3 | M4: RSPM µg/m3 | R4: SPM µg/m3
E5: n | F5: AM | G5: SD | H5: P | I5: n | J5: AM | K5: SD | L5: P | M5: n | N5: AM | O5: SD | P5: P | Q5: GM | R5: n | S5: AM | T5: SD | U5: P | V5: GM
A6: Udyoga Bhawan | B6: 574 | C6: JANUARY | D6: 2024 | E6: ='Udyoga Bhawan'!E46 -> 48 | F6: ='Udyoga Bhawan'!E47 -> 10.855367 | G6: ='Udyoga Bhawan'!E48 -> 1.5947227 | H6: ='Udyoga Bhawan'!E49 -> 14.907407 | I6: ='Udyoga Bhawan'!F46 -> 48 | J6: ='Udyoga Bhawan'!F47 -> 48.823658 | K6: ='Udyoga Bhawan'!F48 -> 10.205779 | L6: ='Udyoga Bhawan'!F49 -> 68.291093 | M6: ='Udyoga Bhawan'!G46 -> 24 | N6: ='Udyoga Bhawan'!G47 -> 125.00035 | O6: ='Udyoga Bhawan'!G48 -> 36.230454 | P6: ='Udyoga Bhawan'!G49 -> 187.37374 | Q6: ='Udyoga Bhawan'!G50 -> 119.35914 | R6: ='Udyoga Bhawan'!H46 -> 24 | S6: ='Udyoga Bhawan'!H47 -> 262.74885 | T6: ='Udyoga Bhawan'!H48 -> 68.544141 | U6: ='Udyoga Bhawan'!H49 -> 431.38261 | V6: ='Udyoga Bhawan'!H50 -> 253.63883
A7: Kupwad | B7: 576 | C7: JANUARY | D7: 2024 | E7: =Kupwad!E45 -> 54 | F7: =Kupwad!E46 -> 12.843472 | G7: =Kupwad!E47 -> 2.5100205 | H7: =Kupwad!E48 -> 18.634259 | I7: =Kupwad!F45 -> 54 | J7: =Kupwad!F46 -> 60.323351 | K7: =Kupwad!F47 -> 8.5081632 | L7: =Kupwad!F48 -> 82.747141 | M7: =Kupwad!G45 -> 27 | N7: =Kupwad!G46 -> 127.70625 | O7: =Kupwad!G47 -> 45.71461 | P7: =Kupwad!G48 -> 250.41667 | Q7: =Kupwad!G49 -> 121.061 | R7: =Kupwad!H45 -> 27 | S7: =Kupwad!H46 -> 261.05047 | T7: =Kupwad!H47 -> 114.73917 | U7: =Kupwad!H48 -> 523.6878 | V7: =Kupwad!H49 -> 240.28039
A8: Rajawada Chowk | B8: 575 | C8: JANUARY | D8: 2024 | E8: ='Rajawada Chowk'!E46 -> 54 | F8: ='Rajawada Chowk'!E47 -> 13.213833 | G8: ='Rajawada Chowk'!E48 -> 2.4786692 | H8: ='Rajawada Chowk'!E49 -> 18.634259 | I8: ='Rajawada Chowk'!F46 -> 54 | J8: ='Rajawada Chowk'!F47 -> 64.268135 | K8: ='Rajawada Chowk'!F48 -> 8.8311023 | L8: ='Rajawada Chowk'!F49 -> 85.05533 | M8: ='Rajawada Chowk'!G46 -> 27 | N8: ='Rajawada Chowk'!G47 -> 118.14836 | O8: ='Rajawada Chowk'!G48 -> 28.616116 | P8: ='Rajawada Chowk'!G49 -> 162.53444 | Q8: ='Rajawada Chowk'!G50 -> 113.32343 | R8: ='Rajawada Chowk'!H46 -> 27 | S8: ='Rajawada Chowk'!H47 -> 224.4596 | T8: ='Rajawada Chowk'!H48 -> 64.069824 | U8: ='Rajawada Chowk'!H49 -> 360.79545 | V8: ='Rajawada Chowk'!H50 -> 216.09464
C11: Note:
C12: ** | D12: All parameters are in µg/m3
C13: n | D13: No. of Samples collected in the Month
C14: AM | D14: Arithmatic Mean
C15: SD | D15: Standard Deviation
C16: P | D16: Peak value of the month
C17: GM | D17: Geomatric Mean of Data
